Workbook
Name payment_transactions_export_1__2: shopify手数料試算!#REF!

Sheet レヴェニューシェア資料
A1: 売上
A2: 項目 | B2: 単価 | C2: 数量 | D2: 小計 | E2: 備考 | G2: 原価 | H2: 小計
A3: オンラインショップ 桐箱2碗 | B3: =ROUND(2000/1.1,0) -> 1818 | C3: 14 | D3: =C3*B3 -> 25452 | G3: =18+620 -> 638 | H3: =G3*C3 -> 8932
A4: オンラインショップ 桐箱1碗 | B4: =ROUND(1000/1.1,0) -> 909 | C4: 7 | D4: =C4*B4 -> 6363 | G4: =18+420 -> 438 | H4: =G4*C4 -> 3066
A5: オンラインショップ 紙袋2碗 | B5: =ROUND(250/1.1,0) -> 227 | C5: 15 | D5: =C5*B5 -> 3405 | G5: =18+103 -> 121 | H5: =G5*C5 -> 1815
A6: オンラインショップ 紙袋1碗 | B6: =ROUND(220/1.1,0) -> 200 | C6: 4 | D6: =C6*B6 -> 800 | G6: =18+99 -> 117 | H6: =G6*C6 -> 468
A7: 売上合計 | C7: =SUM(C3:C6) -> 40 | D7: =SUM(D3:D6) -> 36020 | H7: =SUM(H3:H6) -> 14281
A9: 項目 | B9: 単価 | C9: 数量 | D9: 小計 | E9: 備考
A10: オンラインショップ SHUWAN | B10: =ROUND(D10/C10,0) -> 3900 | C10: 85 | D10: 331500
A11: SHUWAN箱あり | B11: 3150 | C11: 3 | D11: =C11*B11 -> 9450 | E11: COWSI CAMP
A12: SHUWAN箱あり | B12: 2880 | C12: 2 | D12: =C12*B12 -> 5760 | E12: 栗林酒造店
A13: SHUWAN箱あり | B13: 2640 | C13: 90 | D13: =C13*B13 -> 237600 | E13: エルスタイル60碗 小宮酒店30
A14: SHUWAN箱あり | B14: 2516 | C14: 30 | D14: =C14*B14 -> 75480 | E14: エルスタイル60碗 小宮酒店30
A15: SHUWAN箱あり | B15: 2145 | C15: 30 | D15: =C15*B15 -> 64350 | E15: よろずや
A16: SHUWAN箱なし | B16: 2680 | C16: 5 | D16: =C16*B16 -> 13400 | E16: 栗林酒造店
A17: 売上合計 | C17: =SUM(C10:C16) -> 245 | D17: =SUM(D10:D16) -> 737540
A19: Amazon | B19: 単価 | C19: 数量 | D19: 小計 | E19: 備考
A20: アマゾン桐箱 1碗箱 原価 | B20: 420 | C20: 6 | D20: =C20*B20 -> 2520 | E20: アマゾン販売分木箱コスト
A21: アマゾン桐箱 1碗箱 | B21: 0
A22: SHUWAN販売合計金額 | B22: =ROUND(D22/C22,0) -> 3981 | C22: 68 | D22: 270701
A23: プロモーション割引合計 | D23: 2335
A24: Amazon手数料 | D24: 37404
A25: その他+ 保管料 | D25: -25157
A26: その他費用 | D26: 98865 | E26: 広告費用 月額登録料 プロモーション手数料
A27: 合計 | D27: =D22-D23-D24-D25-D26-D20-D21 -> 154734
A29: goooods | B29: 単価 | C29: 数量 | D29: 小計 | E29: 備考
A30: SHUWAN | B30: 3120 | C30: 0 | D30: =C30*B30 -> 0
A31: 取引手数料 | B31: 0 | C31: 0 | D31: =C31*B31 -> 0
A32: 事務手数料 | B32: 0 | C32: 0 | D32: =C32*B32 -> 0
A33: goooods収支合計 | D33: =D30-D31-D32 -> 0
A35: 変動費
A36: 項目 | B36: 単価 | C36: 数量 | D36: 小計 | E36: 備考
A37: SHUWAN原価 | B37: 1260 | C37: =C17+C22+C30 -> 313 | D37: =B37*C37 -> 394380
A38: SHUWAN 転写原価 | B38: 240 | C38: 30 | D38: =B38*C38 -> 7200
A39: 桐箱&紙袋 原価 | B39: =ROUND(D39/C39,0) -> 357 | C39: =C7 -> 40 | D39: =H7 -> 14281
A40: 箱 | B40: 100 | C40: =C17+C22+C30-E40 -> 308 | D40: =B40*C40 -> 30800 | E40: 5
A41: 作家ロイヤリティ | B41: =ROUND(150/1.1,0) -> 136 | C41: =C17 -> 245 | D41: =B41*C41 -> 33320
A42: オンラインショップ手数料 | D42: =ROUND((D7+D10)*0.0373,0) -> 13708 | E42: -0.0373
A43: 変動費 計 | D43: =SUM(D37:D42) -> 493689
A45: 項目 | B45: 金額
...

Sheet Amazon詳細
A1: 日付 | B1: トランザクションステータス | C1: トランザクションの種類 | D1: 注文番号 | E1: 商品の詳細 | F1: 商品価格合計 | G1: プロモーション割引合計 | H1: Amazon手数料 | I1: その他 | J1: 合計 (JPY) | K1: 販売数量 | L1: 桐箱1 | M1: 桐箱2
A2: 日付 | B2: トランザクションステータス | C2: トランザクションの種類 | D2: 注文番号 | E2: 商品の詳細 | F2: 商品価格合計 | G2: プロモーション割引合計 | H2: Amazon手数料 | I2: その他 | J2: 合計 (JPY)
A3: 45961 | B3: 支払い実行済み | C3: 注文に対する支払い | D3: 503-6507365-4120654 | E3: SHUWAN 酒器 おちょこ ぐい呑み 日本酒グラス 270ml 磁器 日本製 ... | F3: 4527 | G3: 0 | H3: -1248 | I3: 403 | J3: 3682 | K3: 1
A4: 45961 | B4: 支払い実行済み | C4: 注文に対する支払い | D4: 503-4838897-6374245 | E4: SHUWAN 酒器 おちょこ ぐい呑み 日本酒グラス 270ml 磁器 日本製 ... | F4: 5436 | G4: 0 | H4: -1432 | I4: 484 | J4: 4488 | K4: 1 | L4: 1
A5: 45960 | B5: 支払い実行済み | C5: 注文に対する支払い | D5: 250-7241853-8131023 | E5: SHUWAN 酒器 おちょこ ぐい呑み 日本酒グラス 270ml 磁器 日本製 ... | F5: 5436 | G5: 0 | H5: -465 | I5: 484 | J5: 5455 | K5: 1 | L5: 1
A6: 45960 | B6: 支払い実行済み | C6: 注文に対する支払い | D6: 249-5148413-9663032 | E6: SHUWAN 酒器 おちょこ ぐい呑み 日本酒グラス 270ml 磁器 日本製 ... | F6: 5436 | G6: 0 | H6: -455 | I6: 484 | J6: 5465 | K6: 1 | L6: 1
A7: 45960 | B7: 支払い実行済み | C7: 注文に対する支払い | D7: 503-7947852-5078213 | E7: SHUWAN 酒器 おちょこ ぐい呑み 日本酒グラス 270ml 磁器 日本製 ... | F7: 4527 | G7: 0 | H7: -689 | I7: 658 | J7: 4496 | K7: 1
A8: 45959 | B8: 支払い実行済み | C8: 注文に対する支払い | D8: 249-6945756-4584663 | E8: SHUWAN 酒器 おちょこ ぐい呑み 日本酒グラス 270ml 磁器 日本製 ... | F8: 5436 | G8: 0 | H8: -455 | I8: 484 | J8: 5465 | K8: 1 | L8: 1
A9: 45958 | B9: 支払い実行済み | C9: 注文に対する支払い | D9: 503-5041815-3680623 | E9: SHUWAN 酒器 おちょこ ぐい呑み 日本酒グラス 270ml 磁器 日本製 ... | F9: 4527 | G9: 0 | H9: -434 | I9: 403 | J9: 4496 | K9: 1
A10: 45956 | B10: 支払い実行済み | C10: 注文に対する支払い | D10: 249-9807028-5987058 | E10: SHUWAN 酒器 おちょこ ぐい呑み 日本酒グラス 270ml 磁器 日本製 ... | F10: 4527 | G10: 0 | H10: -434 | I10: 403 | J10: 4496 | K10: 1
A11: 45956 | B11: 支払い実行済み | C11: サービス料金 | D11: --- | E11: 広告費用 | F11: 0 | G11: 0 | H11: -55332 | I11: 0 | J11: -55332
A12: 45955 | B12: 支払い実行済み | C12: 注文に対する支払い | D12: 250-9117981-9391863 | E12: SHUWAN 酒器 おちょこ ぐい呑み 日本酒グラス 270ml 磁器 日本製 ... | F12: 4042 | G12: 0 | H12: -434 | I12: 354 | J12: 3962 | K12: 1
A13: 45954 | B13: 支払い実行済み | C13: 注文に対する支払い | D13: 249-4377803-5623007 | E13: SHUWAN 酒器 おちょこ ぐい呑み 日本酒グラス 270ml 磁器 日本製 ... | F13: 4527 | G13: -418 | H13: -434 | I13: 821 | J13: 4496 | K13: 1
A14: 45953 | B14: 支払い実行済み | C14: 注文に対する支払い | D14: 250-5392394-6906269 | E14: SHUWAN 酒器 おちょこ ぐい呑み 日本酒グラス 270ml 磁器 日本製 ... | F14: 4527 | G14: -209 | H14: -434 | I14: 612 | J14: 4496 | K14: 1
A15: 45952 | B15: 支払い実行済み | C15: 注文に対する支払い | D15: 249-8057717-4087060 | E15: SHUWAN 酒器 おちょこ ぐい呑み 日本酒グラス 270ml 磁器 日本製 ... | F15: 5436 | G15: -524 | H15: -455 | I15: 464 | J15: 4921 | K15: 1 | L15: 1
A16: 45952 | B16: 支払い実行済み | C16: 注文に対する支払い | D16: 249-7247979-1267822 | E16: SHUWAN 酒器 おちょこ ぐい呑み 日本酒グラス 270ml 磁器 日本製 ... | F16: 4527 | G16: 0 | H16: -434 | I16: 403 | J16: 4496 | K16: 1
A17: 45952 | B17: 支払い実行済み | C17: 注文に対する支払い | D17: 503-6757419-9057433 | E17: SHUWAN 酒器 おちょこ ぐい呑み 日本酒グラス 270ml 磁器 日本製 ... | F17: 4527 | G17: 0 | H17: -434 | I17: 403 | J17: 4496 | K17: 1
A18: 45952 | B18: 支払い実行済み | C18: 注文に対する支払い | D18: 503-0318346-7605449 | E18: SHUWAN 酒器 おちょこ ぐい呑み 日本酒グラス 270ml 磁器 日本製 ... | F18: 4042 | G18: 0 | H18: -434 | I18: 354 | J18: 3962 | K18: 1
A19: 45952 | B19: 支払い実行済み | C19: 注文に対する支払い | D19: 503-4978745-3791025 | E19: SHUWAN 酒器 おちょこ ぐい呑み 日本酒グラス 270ml 磁器 日本製 ... | F19: 4042 | G19: 0 | H19: -434 | I19: 354 | J19: 3962 | K19: 1
A20: 45951 | B20: 支払い実行済み | C20: 注文に対する支払い | D20: 503-5290029-4058202 | E20: SHUWAN 酒器 おちょこ ぐい呑み 日本酒グラス 270ml 磁器 日本製 ... | F20: 4527 | G20: 0 | H20: -434 | I20: 403 | J20: 4496 | K20: 1
A21: 45951 | B21: 支払い実行済み | C21: 注文に対する支払い | D21: 249-7767185-6370210 | E21: SHUWAN 酒器 おちょこ ぐい呑み 日本酒グラス 270ml 磁器 日本製 ... | F21: 4042 | G21: 0 | H21: -434 | I21: 354 | J21: 3962 | K21: 1
A22: 45951 | B22: 支払い実行済み | C22: 注文に対する支払い | D22: 503-6506231-9414205 | E22: SHUWAN 酒器 おちょこ ぐい呑み 日本酒グラス 270ml 磁器 日本製 ... | F22: 4042 | G22: 0 | H22: -434 | I22: 354 | J22: 3962 | K22: 1
A23: 45951 | B23: 支払い実行済み | C23: サービス料金 | D23: 8aa99fb5-c1fb-469f-87af-cffed348a76e | E23: プロモーション手数料 | F23: 0 | G23: 0 | H23: -17600 | I23: 0 | J23: -17600
A24: 45950 | B24: 支払い実行済み | C24: 注文に対する支払い | D24: 249-6663644-0423835 | E24: SHUWAN 酒器 おちょこ ぐい呑み 日本酒グラス 270ml 磁器 日本製 ... | F24: 4042 | G24: 0 | H24: -434 | I24: 354 | J24: 3962 | K24: 1
A25: 45950 | B25: 支払い実行済み | C25: 注文に対する支払い | D25: 249-4029577-1199049 | E25: SHUWAN 酒器 おちょこ ぐい呑み 日本酒グラス 270ml 磁器 日本製 ... | F25: 4042 | G25: 0 | H25: -434 | I25: 354 | J25: 3962 | K25: 1
A26: 45949 | B26: 支払い実行済み | C26: 注文に対する支払い | D26: 503-0340133-1071051 | E26: SHUWAN 酒器 おちょこ ぐい呑み 日本酒グラス 270ml 磁器 日本製 ... | F26: 4042 | G26: 0 | H26: -434 | I26: 354 | J26: 3962 | K26: 1
A27: 45949 | B27: 支払い実行済み | C27: 注文に対する支払い | D27: 249-1103051-2167023 | E27: SHUWAN 酒器 おちょこ ぐい呑み 日本酒グラス 270ml 磁器 日本製 ... | F27: 4042 | G27: 0 | H27: -434 | I27: 354 | J27: 3962 | K27: 1
A28: 45948 | B28: 支払い実行済み | C28: 注文に対する支払い | D28: 503-5198640-9591053 | E28: SHUWAN 酒器 おちょこ ぐい呑み 日本酒グラス 270ml 磁器 日本製 ... | F28: 4042 | G28: 0 | H28: -434 | I28: 354 | J28: 3962 | K28: 1
A29: 45948 | B29: 支払い実行済み | C29: 注文に対する支払い | D29: 503-3427159-6503869 | E29: SHUWAN 酒器 おちょこ ぐい呑み 日本酒グラス 270ml 磁器 日本製 ... | F29: 4042 | G29: 0 | H29: -434 | I29: 354 | J29: 3962 | K29: 1
A30: 45948 | B30: 支払い実行済み | C30: 注文に対する支払い | D30: 249-1306768-1058221 | E30: SHUWAN 酒器 おちょこ ぐい呑み 日本酒グラス 270ml 磁器 日本製 ... | F30: 4042 | G30: 0 | H30: -434 | I30: 354 | J30: 3962 | K30: 1
A31: 45948 | B31: 支払い実行済み | C31: 注文に対する支払い | D31: 249-9848215-2354201 | E31: SHUWAN 酒器 おちょこ ぐい呑み 日本酒グラス 270ml 磁器 日本製 ... | F31: 4042 | G31: 0 | H31: -434 | I31: 354 | J31: 3962 | K31: 1
A32: 45947 | B32: 支払い実行済み | C32: 注文に対する支払い | D32: 503-9813308-5723815 | E32: SHUWAN 酒器 おちょこ ぐい呑み 日本酒グラス 270ml 磁器 日本製 ... | F32: 4042 | G32: 0 | H32: -434 | I32: 354 | J32: 3962 | K32: 1
A33: 45947 | B33: 支払い実行済み | C33: 注文に対する支払い | D33: 249-1205992-0868607 | E33: SHUWAN 酒器 おちょこ ぐい呑み 日本酒グラス 270ml 磁器 日本製 ... | F33: 4042 | G33: 0 | H33: -434 | I33: 354 | J33: 3962 | K33: 1
A34: 45947 | B34: 支払い実行済み | C34: 注文に対する支払い | D34: 249-7770570-1611862 | E34: SHUWAN 酒器 おちょこ ぐい呑み 日本酒グラス 270ml 磁器 日本製 ... | F34: 4042 | G34: 0 | H34: -434 | I34: 354 | J34: 3962 | K34: 1
A35: 45946 | B35: 支払い実行済み | C35: 注文に対する支払い | D35: 250-7497195-4319861 | E35: SHUWAN 酒器 おちょこ ぐい呑み 日本酒グラス 270ml 磁器 日本製 ... | F35: 4042 | G35: 0 | H35: -434 | I35: 354 | J35: 3962 | K35: 1
... A45: 45944 | B45: 支払い実行済み | C45: 注文に対する支払い | D45: 249-2089967-5282227 | E45: SHUWAN 酒器 おちょこ ぐい呑み 日本酒グラス 270ml 磁器 日本製 ... | F45: 4042 | G45: 0 | H45: -434 | I45: 354 | J45: 3962 | K45: 1
A46: 45944 | B46: 支払い実行済み | C46: 注文に対する支払い | D46: 250-8526137-9819067 | E46: SHUWAN 酒器 おちょこ ぐい呑み 日本酒グラス 270ml 磁器 日本製 ... | F46: 5436 | G46: 0 | H46: -434 | I46: 484 | J46: 5486 | K46: 1 | L46: 1
A47: 45943 | B47: 支払い実行済み | C47: 注文に対する支払い | D47: 250-5543658-6480629 | E47: SHUWAN 酒器 おちょこ ぐい呑み 日本酒グラス 270ml 磁器 日本製 ... | F47: 4042 | G47: 0 | H47: -434 | I47: 354 | J47: 3962 | K47: 1
A48: 45943 | B48: 支払い実行済み | C48: 注文に対する支払い | D48: 249-6303647-3383837 | E48: SHUWAN 酒器 おちょこ ぐい呑み 日本酒グラス 270ml 磁器 日本製 ... | F48: 4042 | G48: 0 | H48: -434 | I48: 354 | J48: 3962 | K48: 1
A49: 45943 | B49: 支払い実行済み | C49: 注文に対する支払い | D49: 503-7746013-3289450 | E49: SHUWAN 酒器 おちょこ ぐい呑み 日本酒グラス 270ml 磁器 日本製 ... | F49: 4527 | G49: 0 | H49: -434 | I49: 403 | J49: 4496 | K49: 1
...

Sheet 留保中11月請求時確認
A1: 日付 | B1: トランザクションステータス | C1: トランザクションの種類 | D1: 注文番号 | E1: 商品の詳細 | F1: 商品価格合計 | G1: プロモーション割引合計 | H1: Amazon手数料 | I1: その他 | J1: 合計 (JPY) | K1: 販売数量
A2: 45961 | B2: 留保中 | C2: 注文に対する支払い | D2: 503-5903037-0357468 | E2: SHUWAN 酒器 おちょこ ぐい呑み 日本酒グラス 270ml 磁器 日本製 ... | F2: 4042 | G2: 0 | H2: -1160 | I2: 360 | J2: 3242 | K2: =VLOOKUP(D2,Amazon詳細!D:D,1,0) -> #N/A
A3: 45960 | B3: 留保中 | C3: 注文に対する支払い | D3: 250-6040162-9227042 | E3: SHUWAN 酒器 おちょこ ぐい呑み 日本酒グラス 270ml 磁器 日本製 ... | F3: 4042 | G3: 0 | H3: -1160 | I3: 360 | J3: 3242 | K3: =VLOOKUP(D3,Amazon詳細!D:D,1,0) -> #N/A
A4: 45959 | B4: 留保中 | C4: 注文に対する支払い | D4: 249-7065941-0523003 | E4: SHUWAN 酒器 おちょこ ぐい呑み 日本酒グラス 270ml 磁器 日本製 ... | F4: 12125 | G4: 0 | H4: -3480 | I4: 1081 | J4: 9726 | K4: =VLOOKUP(D4,Amazon詳細!D:D,1,0) -> #N/A
A5: 45959 | B5: 留保中 | C5: 注文に対する支払い | D5: 250-9319205-2697427 | E5: SHUWAN 酒器 おちょこ ぐい呑み 日本酒グラス 270ml 磁器 日本製 ... | F5: 4893 | G5: 0 | H5: -1334 | I5: 435 | J5: 3994 | K5: =VLOOKUP(D5,Amazon詳細!D:D,1,0) -> #N/A
A6: 45958 | B6: 留保中 | C6: 注文に対する支払い | D6: 250-1734693-3409432 | E6: SHUWAN 酒器 おちょこ ぐい呑み 日本酒グラス 270ml 磁器 日本製 ... | F6: 4042 | G6: 0 | H6: -1160 | I6: 360 | J6: 3242 | K6: =VLOOKUP(D6,Amazon詳細!D:D,1,0) -> #N/A
A7: 45957 | B7: 留保中 | C7: 注文に対する支払い | D7: 250-7370376-1357458 | E7: SHUWAN 酒器 おちょこ ぐい呑み 日本酒グラス 270ml 磁器 日本製 ... | F7: 4527 | G7: 0 | H7: -1248 | I7: 403 | J7: 3682 | K7: =VLOOKUP(D7,Amazon詳細!D:D,1,0) -> #N/A
A8: 45957 | B8: 留保中 | C8: 注文に対する支払い | D8: 503-0884348-0303813 | E8: SHUWAN 酒器 おちょこ ぐい呑み 日本酒グラス 270ml 磁器 日本製 ... | F8: 4042 | G8: 0 | H8: -1160 | I8: 360 | J8: 3242 | K8: =VLOOKUP(D8,Amazon詳細!D:D,1,0) -> #N/A

Sheet shopify手数料試算
A1: Payout Date | B1: Status | C1: Charges | D1: Refunds | E1: Adjustments | F1: Marketplace Sales Tax | G1: Advances | H1: Reserved Funds | I1: Fees | J1: Retried Amount | K1: Total | L1: Currency | M1: 手数料率
A2: 45681 | B2: paid | C2: 55220 | D2: 0 | E2: 0 | F2: 0 | G2: 0 | H2: 0 | I2: 1993 | J2: 0 | K2: 53227 | L2: JPY | M2: =I2/K2 -> 0.037443403
A3: 45674 | B3: paid | C3: 15180 | D3: 0 | E3: 0 | F3: 0 | G3: 0 | H3: 0 | I3: 540 | J3: 0 | K3: 14640 | L3: JPY | M3: =I3/K3 -> 0.036885246
A4: 45667 | B4: paid | C4: 55220 | D4: 0 | E4: 0 | F4: 0 | G4: 0 | H4: 0 | I4: 1962 | J4: 0 | K4: 53258 | L4: JPY | M4: =I4/K4 -> 0.036839536
A5: 45663 | B5: paid | C5: 50820 | D5: 0 | E5: 0 | F5: 0 | G5: 0 | H5: 0 | I5: 1805 | J5: 0 | K5: 49015 | L5: JPY | M5: =I5/K5 -> 0.036825462
A6: 45653 | B6: paid | C6: 91300 | D6: 0 | E6: 0 | F6: 0 | G6: 0 | H6: 0 | I6: 3273 | J6: 0 | K6: 88027 | L6: JPY | M6: =I6/K6 -> 0.037181774
A7: 45646 | B7: paid | C7: 52360 | D7: 0 | E7: 0 | F7: 0 | G7: 0 | H7: 0 | I7: 1909 | J7: 0 | K7: 50451 | L7: JPY | M7: =I7/K7 -> 0.037838695
A8: 45639 | B8: paid | C8: 39380 | D8: 0 | E8: 0 | F8: 0 | G8: 0 | H8: 0 | I8: 1400 | J8: 0 | K8: 37980 | L8: JPY | M8: =I8/K8 -> 0.036861506
A9: 45632 | B9: paid | C9: 28160 | D9: 0 | E9: 0 | F9: 0 | G9: 0 | H9: 0 | I9: 1000 | J9: 0 | K9: 27160 | L9: JPY | M9: =I9/K9 -> 0.036818851
A10: 45625 | B10: paid | C10: 32120 | D10: 0 | E10: 0 | F10: 0 | G10: 0 | H10: 0 | I10: 1141 | J10: 0 | K10: 30979 | L10: JPY | M10: =I10/K10 -> 0.036831402
A11: 45618 | B11: paid | C11: 37180 | D11: 0 | E11: 0 | F11: 0 | G11: 0 | H11: 0 | I11: 1321 | J11: 0 | K11: 35859 | L11: JPY | M11: =I11/K11 -> 0.036838729
A12: 45611 | B12: paid | C12: 61380 | D12: 0 | E12: 0 | F12: 0 | G12: 0 | H12: 0 | I12: 2244 | J12: 0 | K12: 59136 | L12: JPY | M12: =I12/K12 -> 0.037946429
A13: 45604 | B13: paid | C13: 15180 | D13: 0 | E13: 0 | F13: 0 | G13: 0 | H13: 0 | I13: 540 | J13: 0 | K13: 14640 | L13: JPY | M13: =I13/K13 -> 0.036885246
... A16: 45576 | B16: paid | C16: 254320 | D16: 0 | E16: 0 | F16: 0 | G16: 0 | H16: 0 | I16: 9246 | J16: 0 | K16: 245074 | L16: JPY | M16: =I16/K16 -> 0.03772738
A17: 合計 | I17: =SUM(I2:I16) -> 35731 | K17: =SUM(K2:K16) -> 958229 | M17: =I17/K17 -> 0.037288581
