Workbook
Name payment_transactions_export_1__2: shopify手数料試算!#REF!

Sheet レヴェニューシェア資料
A1: 売上
A2: 項目 | B2: 単価 | C2: 数量 | D2: 小計 | E2: 備考 | G2: 原価 | H2: 小計
A3: オンラインショップ 桐箱2碗 | B3: =ROUND(2000/1.1,0) -> 1818 | C3: 15 | D3: =C3*B3 -> 27270 | G3: =18+620 -> 638 | H3: =G3*C3 -> 9570
A4: オンラインショップ 桐箱1碗 | B4: =ROUND(1000/1.1,0) -> 909 | C4: 3 | D4: =C4*B4 -> 2727 | G4: =18+420 -> 438 | H4: =G4*C4 -> 1314
A5: オンラインショップ 紙袋2碗 | B5: =ROUND(250/1.1,0) -> 227 | C5: 17 | D5: =C5*B5 -> 3859 | G5: =18+103 -> 121 | H5: =G5*C5 -> 2057
A6: オンラインショップ 紙袋1碗 | B6: =ROUND(220/1.1,0) -> 200 | C6: 3 | D6: =C6*B6 -> 600 | G6: =18+99 -> 117 | H6: =G6*C6 -> 351
A7: 売上合計 | C7: =SUM(C3:C6) -> 38 | D7: =SUM(D3:D6) -> 34456 | H7: =SUM(H3:H6) -> 13292
A9: 項目 | B9: 単価 | C9: 数量 | D9: 小計 | E9: 備考
A10: そそぎ売上 | B10: 1000 | C10: 21 | D10: =C10*B10 -> 21000 | E10: 小宮商店21
A12: 項目 | B12: 単価 | C12: 数量 | D12: 小計 | E12: 備考
A13: オンラインショップ SHUWAN陶胎漆器 | B13: 18000 | C13: 3 | D13: =C13*B13 -> 54000
A14: オンラインショップ SHUWAN | B14: 3900 | C14: 64 | D14: =C14*B14 -> 249600
A15: SHUWAN箱なし | B15: 2950 | C15: 30 | D15: =C15*B15 -> 88500 | E15: 炭之囲 ためえもん 20 J-CAT 10
A16: SHUWAN箱あり | B16: 2640 | C16: 162 | D16: =C16*B16 -> 427680 | E16: 島酒店10 ナビッピドットコム30 酒泉洞掘一30 エルスタイル30 小宮商店30 ワインショップ武田30
A17: 売上合計 | C17: =SUM(C13:C16) -> 259 | D17: =SUM(D10:D16) -> 840780 | E17: そそぎ込み
A19: Amazon | B19: 平均単価 | C19: 数量 | D19: 小計 | E19: 備考
A20: アマゾン桐箱 1碗箱 原価 | B20: 420 | C20: 15 | D20: =C20*B20 -> 6300 | E20: アマゾン販売分木箱コスト
A21: アマゾン桐箱 2碗箱 原価 | C21: 0
A22: SHUWAN販売合計金額 | B22: =ROUND(D22/C22,0) -> 4137 | C22: 61 | D22: 252365
A23: プロモーション割引合計 | D23: 1694
A24: Amazon手数料 | D24: 37894
A25: その他+ 保管料 | D25: -25695
A26: その他費用 | D26: 64780 | E26: 広告費用 月額登録料 プロモーション手数料
A27: 合計 | D27: =D22-D23-D24-D25-D26-D20-D21 -> 167392
A29: goooods | B29: 単価 | C29: 数量 | D29: 小計 | E29: 備考
A30: SHUWAN | B30: 3120 | C30: 0 | D30: =C30*B30 -> 0
A31: 取引手数料 | B31: 0 | C31: 0 | D31: =C31*B31 -> 0
A32: 事務手数料 | B32: 0 | C32: 0 | D32: =C32*B32 -> 0
A33: goooods収支合計 | D33: =D30-D31-D32 -> 0
A35: 変動費
A36: 項目 | B36: 単価 | C36: 数量 | D36: 小計 | E36: 備考
A37: 送料値引き | B37: 1000 | C37: 21 | D37: =B37*C37 -> 21000
A38: SHUWAN陶胎漆器 原価 | B38: 6500 | C38: =C13 -> 3 | D38: =B38*C38 -> 19500
A39: SHUWAN原価 | B39: 1260 | C39: =C17+C22+C30-C13 -> 317 | D39: =B39*C39 -> 399420
A40: 桐箱&紙袋 原価 | B40: =ROUND(D40/C40,0) -> 350 | C40: =C7 -> 38 | D40: =H7 -> 13292
A41: 箱 | B41: 100 | C41: =C17+C22+C30-E41 -> 290 | D41: =B41*C41 -> 29000 | E41: 30
A42: 作家ロイヤリティ | B42: =ROUND(150/1.1,0) -> 136 | C42: =C17-E42 -> 257 | D42: =B42*C42 -> 34952 | E42: 2
A43: オンラインショップ手数料 | D43: =ROUND((D7+D14)*0.0373,0) -> 10595 | E43: -0.0373
A44: そそぎ原価 | B44: 500 | C44: 21 | D44: =B44*C44 -> 10500
A45: 変動費 計 | D45: =SUM(D37:D43) -> 527759
...

Sheet Amazon詳細
A1: 日付 | B1: トランザクションステータス | C1: トランザクションの種類 | D1: 注文番号 | E1: 商品の詳細 | F1: 商品価格合計 | G1: プロモーション割引合計 | H1: Amazon手数料 | I1: その他 | J1: 合計 (JPY) | K1: 販売数量 | L1: 桐箱1 | M1: 桐箱2
A2: 45991 | B2: 支払い実行済み | C2: 注文に対する支払い | D2: 250-8954102-9391017 | E2: SHUWAN 酒器 おちょこ ぐい呑み 日本酒グラス 270ml 磁器 日本製 ... | F2: 4042 | G2: 0 | H2: -1160 | I2: 360 | J2: 3242 | K2: 1
A3: 45991 | B3: 支払い実行済み | C3: 注文に対する支払い | D3: 503-9834022-3802236 | E3: SHUWAN 酒器 おちょこ ぐい呑み 日本酒グラス 270ml 磁器 日本製 ... | F3: 4042 | G3: 0 | H3: -1160 | I3: 360 | J3: 3242 | K3: 1
A4: 45991 | B4: 支払い実行済み | C4: 注文に対する支払い | D4: 503-3787157-8335851 | E4: SHUWAN 酒器 おちょこ ぐい呑み 日本酒グラス 270ml 磁器 日本製 ... | F4: 4042 | G4: 0 | H4: -434 | I4: 360 | J4: 3968 | K4: 1
A5: 45988 | B5: 支払い実行済み | C5: 注文に対する支払い | D5: 250-5124994-7275808 | E5: SHUWAN 酒器 おちょこ ぐい呑み 日本酒グラス 270ml 磁器 日本製 ... | F5: 5436 | G5: -455 | H5: -455 | I5: 395 | J5: 4921 | K5: 0 | L5: 1
A6: 45987 | B6: 支払い実行済み | C6: 注文に対する支払い | D6: 250-6891371-8622268 | E6: SHUWAN 酒器 おちょこ ぐい呑み 日本酒グラス 270ml 磁器 日本製 ... | F6: 5436 | G6: 0 | H6: -455 | I6: 484 | J6: 5465 | K6: 0 | L6: 1
A7: 45987 | B7: 支払い実行済み | C7: 注文に対する支払い | D7: 503-8678431-4621422 | E7: SHUWAN 酒器 おちょこ ぐい呑み 日本酒グラス 270ml 磁器 日本製 ... | F7: 4527 | G7: 0 | H7: -434 | I7: 403 | J7: 4496 | K7: 1
A8: 45986 | B8: 支払い実行済み | C8: サービス料金 | D8: --- | E8: 広告費用 | F8: 0 | G8: 0 | H8: -55834 | I8: 0 | J8: -55834 | K8: 0
A9: 45986 | B9: 支払い実行済み | C9: 注文に対する支払い | D9: 249-8308517-4244639 | E9: SHUWAN 酒器 おちょこ ぐい呑み 日本酒グラス 270ml 磁器 日本製 ... | F9: 4527 | G9: 0 | H9: -434 | I9: 403 | J9: 4496 | K9: 1
A10: 45986 | B10: 支払い実行済み | C10: 注文に対する支払い | D10: 250-3742431-2491028 | E10: SHUWAN 酒器 おちょこ ぐい呑み 日本酒グラス 270ml 磁器 日本製 ... | F10: 5436 | G10: 0 | H10: -455 | I10: 484 | J10: 5465 | K10: 0 | L10: 1
A11: 45986 | B11: 支払い実行済み | C11: 注文に対する支払い | D11: 249-1271549-1624648 | E11: SHUWAN 酒器 おちょこ ぐい呑み 日本酒グラス 270ml 磁器 日本製 ... | F11: 4041 | G11: -4 | H11: -434 | I11: 365 | J11: 3968 | K11: 1
A12: 45986 | B12: 支払い実行済み | C12: 注文に対する支払い | D12: 249-8595065-4910235 | E12: SHUWAN 酒器 おちょこ ぐい呑み 日本酒グラス 270ml 磁器 日本製 ... | F12: 5436 | G12: -140 | H12: -455 | I12: 624 | J12: 5465 | K12: 0 | L12: 1
A13: 45985 | B13: 支払い実行済み | C13: 注文に対する支払い | D13: 503-9432693-3415801 | E13: SHUWAN 酒器 おちょこ ぐい呑み 日本酒グラス 270ml 磁器 日本製 ... | F13: 4527 | G13: -84 | H13: -434 | I13: 487 | J13: 4496 | K13: 1
A14: 45985 | B14: 支払い実行済み | C14: 注文に対する支払い | D14: 503-9432693-3415801 | E14: SHUWAN 酒器 おちょこ ぐい呑み 日本酒グラス 270ml 磁器 日本製 ... | F14: 4527 | G14: -84 | H14: -434 | I14: 487 | J14: 4496 | K14: 1
A15: 45985 | B15: 支払い実行済み | C15: 注文に対する支払い | D15: 250-6981260-6800624 | E15: SHUWAN 酒器 おちょこ ぐい呑み 日本酒グラス 270ml 磁器 日本製 ... | F15: 9055 | G15: 0 | H15: -868 | I15: 805 | J15: 8992 | K15: 2
A16: 45985 | B16: 支払い実行済み | C16: 返金 | D16: 249-9560513-3771000 | E16: SHUWAN 酒器 おちょこ ぐい呑み 日本酒グラス 270ml 磁器 日本製 ... | F16: -5436 | G16: 0 | H16: 0 | I16: -484 | J16: -5920 | K16: 0 | L16: -1
A17: 45985 | B17: 支払い実行済み | C17: 注文に対する支払い | D17: 503-3478844-4646258 | E17: SHUWAN 酒器 おちょこ ぐい呑み 日本酒グラス 270ml 磁器 日本製 ... | F17: 4527 | G17: 0 | H17: -434 | I17: 403 | J17: 4496 | K17: 1
A18: 45984 | B18: 支払い実行済み | C18: 注文に対する支払い | D18: 250-5932727-3878231 | E18: SHUWAN 酒器 おちょこ ぐい呑み 日本酒グラス 270ml 磁器 日本製 ... | F18: 4527 | G18: 0 | H18: -434 | I18: 403 | J18: 4496 | K18: 1
A19: 45984 | B19: 支払い実行済み | C19: 注文に対する支払い | D19: 249-9560513-3771000 | E19: SHUWAN 酒器 おちょこ ぐい呑み 日本酒グラス 270ml 磁器 日本製 ... | F19: 5436 | G19: 0 | H19: -455 | I19: 484 | J19: 5465 | K19: 0 | L19: 1
A20: 45984 | B20: 支払い実行済み | C20: 注文に対する支払い | D20: 503-5950374-8490244 | E20: SHUWAN 酒器 おちょこ ぐい呑み 日本酒グラス 270ml 磁器 日本製 ... | F20: 9055 | G20: 0 | H20: -868 | I20: 805 | J20: 8992 | K20: 2
A21: 45984 | B21: 支払い実行済み | C21: 注文に対する支払い | D21: 249-1065897-9038216 | E21: SHUWAN 酒器 おちょこ ぐい呑み 日本酒グラス 270ml 磁器 日本製 ... | F21: 5436 | G21: 0 | H21: -455 | I21: 484 | J21: 5465 | K21: 0 | L21: 1
A22: 45983 | B22: 支払い実行済み | C22: 注文に対する支払い | D22: 503-0261299-8147867 | E22: SHUWAN 酒器 おちょこ ぐい呑み 日本酒グラス 270ml 磁器 日本製 ... | F22: 4527 | G22: 0 | H22: -434 | I22: 403 | J22: 4496 | K22: 1
A23: 45981 | B23: 支払い実行済み | C23: 注文に対する支払い | D23: 250-8348899-3794202 | E23: SHUWAN 酒器 おちょこ ぐい呑み 日本酒グラス 270ml 磁器 日本製 ... | F23: 5436 | G23: 0 | H23: -455 | I23: 484 | J23: 5465 | K23: 0 | L23: 1
A24: 45981 | B24: 支払い実行済み | C24: 注文に対する支払い | D24: 249-8928561-7114211 | E24: SHUWAN 酒器 おちょこ ぐい呑み 日本酒グラス 270ml 磁器 日本製 ... | F24: 4527 | G24: -60 | H24: -434 | I24: 463 | J24: 4496 | K24: 1
A25: 45979 | B25: 支払い実行済み | C25: 注文に対する支払い | D25: 250-9919626-4787055 | E25: SHUWAN 酒器 おちょこ ぐい呑み 日本酒グラス 270ml 磁器 日本製 ... | F25: 4042 | G25: 0 | H25: -434 | I25: 360 | J25: 3968 | K25: 1
A26: 45979 | B26: 支払い実行済み | C26: 注文に対する支払い | D26: 250-3322077-0233440 | E26: SHUWAN 酒器 おちょこ ぐい呑み 日本酒グラス 270ml 磁器 日本製 ... | F26: 4527 | G26: 0 | H26: -434 | I26: 403 | J26: 4496 | K26: 1
A27: 45979 | B27: 支払い実行済み | C27: 注文に対する支払い | D27: 249-8699371-1530228 | E27: SHUWAN 酒器 おちょこ ぐい呑み 日本酒グラス 270ml 磁器 日本製 ... | F27: 4527 | G27: 0 | H27: -434 | I27: 403 | J27: 4496 | K27: 1
A28: 45978 | B28: 支払い実行済み | C28: 注文に対する支払い | D28: 249-1634951-3468633 | E28: SHUWAN 酒器 おちょこ ぐい呑み 日本酒グラス 270ml 磁器 日本製 ... | F28: 4527 | G28: 0 | H28: -434 | I28: 403 | J28: 4496 | K28: 1
A29: 45977 | B29: 支払い実行済み | C29: 注文に対する支払い | D29: 503-2578347-7759823 | E29: SHUWAN 酒器 おちょこ ぐい呑み 日本酒グラス 270ml 磁器 日本製 ... | F29: 10873 | G29: 0 | H29: -910 | I29: 967 | J29: 10930 | K29: 0 | L29: 2
A30: 45977 | B30: 支払い実行済み | C30: 返金 | D30: 250-3921390-8347859 | E30: SHUWAN 酒器 おちょこ ぐい呑み 日本酒グラス 270ml 磁器 日本製 ... | F30: -9055 | G30: 0 | H30: 0 | I30: -810 | J30: -9865 | K30: -2
A31: 45977 | B31: 支払い実行済み | C31: 注文に対する支払い | D31: 503-0385788-6279006 | E31: SHUWAN 酒器 おちょこ ぐい呑み 日本酒グラス 270ml 磁器 日本製 ... | F31: 5436 | G31: 0 | H31: -612 | I31: 641 | J31: 5465 | K31: 0 | L31: 1
A32: 45977 | B32: 支払い実行済み | C32: 注文に対する支払い | D32: 249-0388745-2832655 | E32: SHUWAN 酒器 おちょこ ぐい呑み 日本酒グラス 270ml 磁器 日本製 ... | F32: 5436 | G32: 0 | H32: -455 | I32: 484 | J32: 5465 | K32: 0 | L32: 1
A33: 45977 | B33: 支払い実行済み | C33: 注文に対する支払い | D33: 250-2482330-1079802 | E33: SHUWAN 酒器 おちょこ ぐい呑み 日本酒グラス 270ml 磁器 日本製 ... | F33: 4527 | G33: 0 | H33: -788 | I33: 757 | J33: 4496 | K33: 1
A34: 45976 | B34: 支払い実行済み | C34: 注文に対する支払い | D34: 503-8042438-0183809 | E34: SHUWAN 酒器 おちょこ ぐい呑み 日本酒グラス 270ml 磁器 日本製 ... | F34: 4527 | G34: 0 | H34: -434 | I34: 403 | J34: 4496 | K34: 1
A35: 45976 | B35: 支払い実行済み | C35: 注文に対する支払い | D35: 250-3852806-7790259 | E35: SHUWAN 酒器 おちょこ ぐい呑み 日本酒グラス 270ml 磁器 日本製 ... | F35: 4527 | G35: -182 | H35: -434 | I35: 585 | J35: 4496 | K35: 1
A36: 45976 | B36: 支払い実行済み | C36: 注文に対する支払い | D36: 250-7578995-3405464 | E36: SHUWAN 酒器 おちょこ ぐい呑み 日本酒グラス 270ml 磁器 日本製 ... | F36: 4042 | G36: 0 | H36: -434 | I36: 360 | J36: 3968 | K36: 1
A37: 45976 | B37: 支払い実行済み | C37: 返金 | D37: 250-3852806-7790259 | E37: SHUWAN 酒器 おちょこ ぐい呑み 日本酒グラス 270ml 磁器 日本製 ... | F37: -4527 | G37: 182 | H37: 0 | I37: -585 | J37: -4930 | K37: -1
A38: 45976 | B38: 支払い実行済み | C38: 注文に対する支払い | D38: 250-3921390-8347859 | E38: SHUWAN 酒器 おちょこ ぐい呑み 日本酒グラス 270ml 磁器 日本製 ... | F38: 9055 | G38: 0 | H38: -868 | I38: 805 | J38: 8992 | K38: 2
A39: 45975 | B39: 支払い実行済み | C39: 注文に対する支払い | D39: 250-5810668-7487024 | E39: SHUWAN 酒器 おちょこ ぐい呑み 日本酒グラス 270ml 磁器 日本製 ... | F39: 4527 | G39: 0 | H39: -434 | I39: 403 | J39: 4496 | K39: 1
A40: 45975 | B40: 支払い実行済み | C40: 注文に対する支払い | D40: 249-3247428-3539807 | E40: SHUWAN 酒器 おちょこ ぐい呑み 日本酒グラス 270ml 磁器 日本製 ... | F40: 4527 | G40: 0 | H40: -434 | I40: 403 | J40: 4496 | K40: 1
...

Sheet 留保中12月請求時確認
A1: 日付 | B1: トランザクションステータス | C1: トランザクションの種類 | D1: 注文番号 | E1: 商品の詳細 | F1: 商品価格合計 | G1: プロモーション割引合計 | H1: Amazon手数料 | I1: その他 | J1: 合計 (JPY) | K1: 番号確認
A2: 45991 | B2: 留保中 | C2: 注文に対する支払い | D2: 503-2013545-5135033 | E2: SHUWAN 酒器 おちょこ ぐい呑み 日本酒グラス 270ml 磁器 日本製 ... | F2: 4042 | G2: 0 | H2: -1160 | I2: 360 | J2: 3242 | K2: =VLOOKUP(D2,Amazon詳細!D:D,1,0) -> #N/A
A3: 45991 | B3: 留保中 | C3: 注文に対する支払い | D3: 249-3184163-2910201 | E3: SHUWAN 酒器 おちょこ ぐい呑み 日本酒グラス 270ml 磁器 日本製 ... | F3: 8084 | G3: -1162 | H3: -2188 | I3: 1074 | J3: 5808 | K3: =VLOOKUP(D3,Amazon詳細!D:D,1,0) -> #N/A
A4: 45990 | B4: 留保中 | C4: 注文に対する支払い | D4: 250-4650511-7734228 | E4: SHUWAN 酒器 おちょこ ぐい呑み 日本酒グラス 270ml 磁器 日本製 ... | F4: 4042 | G4: -418 | H4: -1160 | I4: 778 | J4: 3242 | K4: =VLOOKUP(D4,Amazon詳細!D:D,1,0) -> #N/A
A5: 45990 | B5: 留保中 | C5: 注文に対する支払い | D5: 249-4168228-6351862 | E5: SHUWAN 酒器 おちょこ ぐい呑み 日本酒グラス 270ml 磁器 日本製 ... | F5: 16167 | G5: 0 | H5: -4640 | I5: 1441 | J5: 12968 | K5: =VLOOKUP(D5,Amazon詳細!D:D,1,0) -> #N/A
A6: 45990 | B6: 留保中 | C6: 注文に対する支払い | D6: 503-3715259-9108626 | E6: SHUWAN 酒器 おちょこ ぐい呑み 日本酒グラス 270ml 磁器 日本製 ... | F6: 4042 | G6: 0 | H6: -1160 | I6: 360 | J6: 3242 | K6: =VLOOKUP(D6,Amazon詳細!D:D,1,0) -> #N/A
A7: 45989 | B7: 留保中 | C7: 注文に対する支払い | D7: 249-9837720-3591833 | E7: SHUWAN 酒器 おちょこ ぐい呑み 日本酒グラス 270ml 磁器 日本製 ... | F7: 4042 | G7: 0 | H7: -1160 | I7: 360 | J7: 3242 | K7: =VLOOKUP(D7,Amazon詳細!D:D,1,0) -> #N/A
A8: 45989 | B8: 留保中 | C8: 注文に対する支払い | D8: 250-6265678-5643029 | E8: SHUWAN 酒器 おちょこ ぐい呑み 日本酒グラス 270ml 磁器 日本製 ... | F8: 4042 | G8: 0 | H8: -1160 | I8: 360 | J8: 3242 | K8: =VLOOKUP(D8,Amazon詳細!D:D,1,0) -> #N/A
A9: 45989 | B9: 留保中 | C9: 注文に対する支払い | D9: 503-7751489-9509403 | E9: SHUWAN 酒器 おちょこ ぐい呑み 日本酒グラス 270ml 磁器 日本製 ... | F9: 4042 | G9: 0 | H9: -1160 | I9: 360 | J9: 3242 | K9: =VLOOKUP(D9,Amazon詳細!D:D,1,0) -> #N/A
A10: 45989 | B10: 留保中 | C10: 注文に対する支払い | D10: 249-3087859-9163022 | E10: SHUWAN 酒器 おちょこ ぐい呑み 日本酒グラス 270ml 磁器 日本製 ... | F10: 4042 | G10: 0 | H10: -1160 | I10: 360 | J10: 3242 | K10: =VLOOKUP(D10,Amazon詳細!D:D,1,0) -> #N/A
A11: 45989 | B11: 留保中 | C11: 注文に対する支払い | D11: 249-0662433-6281460 | E11: SHUWAN 酒器 おちょこ ぐい呑み 日本酒グラス 270ml 磁器 日本製 ... | F11: 4042 | G11: 0 | H11: -1160 | I11: 360 | J11: 3242 | K11: =VLOOKUP(D11,Amazon詳細!D:D,1,0) -> #N/A
A12: 45989 | B12: 留保中 | C12: 注文に対する支払い | D12: 249-7888061-2015835 | E12: SHUWAN 酒器 おちょこ ぐい呑み 日本酒グラス 270ml 磁器 日本製 ... | F12: 4893 | G12: 0 | H12: -1334 | I12: 435 | J12: 3994 | K12: =VLOOKUP(D12,Amazon詳細!D:D,1,0) -> #N/A
A13: 45988 | B13: 留保中 | C13: 注文に対する支払い | D13: 250-8033166-3884610 | E13: SHUWAN 酒器 おちょこ ぐい呑み 日本酒グラス 270ml 磁器 日本製 ... | F13: 4893 | G13: 0 | H13: -1334 | I13: 435 | J13: 3994 | K13: =VLOOKUP(D13,Amazon詳細!D:D,1,0) -> #N/A
... A26: 45983 | B26: 留保中 | C26: 注文に対する支払い | D26: 503-5051714-0721457 | E26: SHUWAN 酒器 おちょこ ぐい呑み 日本酒グラス 270ml 磁器 日本製 ... | F26: 4042 | G26: -806 | H26: -1094 | I26: 762 | J26: 2904 | K26: =VLOOKUP(D26,Amazon詳細!D:D,1,0) -> #N/A

Sheet shopify手数料試算
A1: Payout Date | B1: Status | C1: Charges | D1: Refunds | E1: Adjustments | F1: Marketplace Sales Tax | G1: Advances | H1: Reserved Funds | I1: Fees | J1: Retried Amount | K1: Total | L1: Currency | M1: 手数料率
A2: 45681 | B2: paid | C2: 55220 | D2: 0 | E2: 0 | F2: 0 | G2: 0 | H2: 0 | I2: 1993 | J2: 0 | K2: 53227 | L2: JPY | M2: =I2/K2 -> 0.037443403
A3: 45674 | B3: paid | C3: 15180 | D3: 0 | E3: 0 | F3: 0 | G3: 0 | H3: 0 | I3: 540 | J3: 0 | K3: 14640 | L3: JPY | M3: =I3/K3 -> 0.036885246
A4: 45667 | B4: paid | C4: 55220 | D4: 0 | E4: 0 | F4: 0 | G4: 0 | H4: 0 | I4: 1962 | J4: 0 | K4: 53258 | L4: JPY | M4: =I4/K4 -> 0.036839536
A5: 45663 | B5: paid | C5: 50820 | D5: 0 | E5: 0 | F5: 0 | G5: 0 | H5: 0 | I5: 1805 | J5: 0 | K5: 49015 | L5: JPY | M5: =I5/K5 -> 0.036825462
A6: 45653 | B6: paid | C6: 91300 | D6: 0 | E6: 0 | F6: 0 | G6: 0 | H6: 0 | I6: 3273 | J6: 0 | K6: 88027 | L6: JPY | M6: =I6/K6 -> 0.037181774
A7: 45646 | B7: paid | C7: 52360 | D7: 0 | E7: 0 | F7: 0 | G7: 0 | H7: 0 | I7: 1909 | J7: 0 | K7: 50451 | L7: JPY | M7: =I7/K7 -> 0.037838695
A8: 45639 | B8: paid | C8: 39380 | D8: 0 | E8: 0 | F8: 0 | G8: 0 | H8: 0 | I8: 1400 | J8: 0 | K8: 37980 | L8: JPY | M8: =I8/K8 -> 0.036861506
A9: 45632 | B9: paid | C9: 28160 | D9: 0 | E9: 0 | F9: 0 | G9: 0 | H9: 0 | I9: 1000 | J9: 0 | K9: 27160 | L9: JPY | M9: =I9/K9 -> 0.036818851
A10: 45625 | B10: paid | C10: 32120 | D10: 0 | E10: 0 | F10: 0 | G10: 0 | H10: 0 | I10: 1141 | J10: 0 | K10: 30979 | L10: JPY | M10: =I10/K10 -> 0.036831402
A11: 45618 | B11: paid | C11: 37180 | D11: 0 | E11: 0 | F11: 0 | G11: 0 | H11: 0 | I11: 1321 | J11: 0 | K11: 35859 | L11: JPY | M11: =I11/K11 -> 0.036838729
A12: 45611 | B12: paid | C12: 61380 | D12: 0 | E12: 0 | F12: 0 | G12: 0 | H12: 0 | I12: 2244 | J12: 0 | K12: 59136 | L12: JPY | M12: =I12/K12 -> 0.037946429
A13: 45604 | B13: paid | C13: 15180 | D13: 0 | E13: 0 | F13: 0 | G13: 0 | H13: 0 | I13: 540 | J13: 0 | K13: 14640 | L13: JPY | M13: =I13/K13 -> 0.036885246
... A16: 45576 | B16: paid | C16: 254320 | D16: 0 | E16: 0 | F16: 0 | G16: 0 | H16: 0 | I16: 9246 | J16: 0 | K16: 245074 | L16: JPY | M16: =I16/K16 -> 0.03772738
A17: 合計 | I17: =SUM(I2:I16) -> 35731 | K17: =SUM(K2:K16) -> 958229 | M17: =I17/K17 -> 0.037288581
