Workbook
Name payment_transactions_export_1__2: shopify手数料試算!#REF!

Sheet レヴェニューシェア資料
A1: 売上
A2: 項目 | B2: 単価 | C2: 数量 | D2: 小計 | E2: 備考 | G2: 原価 | H2: 小計
A3: オンラインショップ 桐箱2碗 | B3: =ROUND(2000/1.1,0) -> 1818 | C3: 39 | D3: 35451 | G3: =18+620 -> 638 | H3: =G3*C3 -> 24882
A4: オンラインショップ 桐箱1碗 | B4: =ROUND(1000/1.1,0) -> 909 | C4: 13 | D4: 23634 | G4: =18+420 -> 438 | H4: =G4*C4 -> 5694
A5: オンラインショップ 紙袋2碗 | B5: =ROUND(250/1.1,0) -> 227 | C5: 35 | D5: 7000 | G5: =18+103 -> 121 | H5: =G5*C5 -> 4235
A6: オンラインショップ 紙袋1碗 | B6: =ROUND(220/1.1,0) -> 200 | C6: 7 | D6: 1589 | G6: =18+99 -> 117 | H6: =G6*C6 -> 819
A7: 売上合計 | C7: =SUM(C3:C6) -> 94 | D7: =SUM(D3:D6) -> 67674 | H7: =SUM(H3:H6) -> 35630
A9: 項目 | B9: 単価 | C9: 数量 | D9: 小計 | E9: 備考
D10: =C10*B10 -> 0
A12: 項目 | B12: 単価 | C12: 数量 | D12: 小計 | E12: 備考
A13: オンラインショップ SHUWAN陶胎漆器 | B13: 18000 | C13: 9 | D13: =C13*B13 -> 162000
A14: オンラインショップ SHUWAN | B14: 3900 | C14: 181 | D14: =C14*B14 -> 705900
A15: しゅわんグラス箱無し ロゴなし | B15: 2160 | C15: 12 | D15: =C15*B15 -> 25920
A16: SHUWAN箱なし | B16: 2650 | C16: 30 | D16: =C16*B16 -> 79500 | E16: ほうちょう
A17: SHUWAN箱なし | B17: 2440 | C17: 30 | D17: =C17*B17 -> 73200 | E17: 森ノ醸造所
A18: SHUWAN箱あり | B18: 2880 | C18: 40 | D18: =C18*B18 -> 115200 | E18: たまき酒店8 福司酒造10 東市酒店10 長谷川屋12
A19: SHUWAN箱あり | B19: 2640 | C19: 270 | D19: =C19*B19 -> 712800 | E19: 森田酒店12 パシオンエナチュール12 酒ハウスモリモト24 渡邉宗田商店12 エルスタイル90 LocalDesign90 酒泉洞堀一30
A20: 売上合計 | C20: =SUM(C13:C19) -> 572 | D20: =SUM(D10:D19) -> 1874520
A22: Amazon | B22: 平均単価 | C22: 数量 | D22: 小計 | E22: 備考
A23: アマゾン桐箱 1碗箱 原価 | B23: 420 | C23: 21 | D23: =C23*B23 -> 8820 | E23: アマゾン販売分木箱コスト
A24: アマゾン桐箱 2碗箱 原価 | B24: 620 | C24: 2 | D24: =C24*B24 -> 1240
A25: SHUWAN販売合計金額 | B25: =ROUND(D25/C25,0) -> 3978 | C25: 134 | D25: 533118 | E25: 11月分1個調整
A26: プロモーション割引合計 | D26: 6637
A27: Amazon手数料 | D27: 98628
A28: その他+ 保管料 | D28: -52940
A29: その他費用 | D29: 94746 | E29: 広告費用 月額登録料 プロモーション手数料
A30: 合計 | D30: =D25-D26-D27-D28-D29-D23-D24 -> 375987
A32: goooods | B32: 単価 | C32: 数量 | D32: 小計 | E32: 備考
A33: SHUWAN | B33: 3120 | C33: 0 | D33: =C33*B33 -> 0
A34: 取引手数料 | B34: 0 | C34: 0 | D34: =C34*B34 -> 0
A35: 事務手数料 | B35: 0 | C35: 0 | D35: =C35*B35 -> 0
A36: goooods収支合計 | D36: =D33-D34-D35 -> 0
A38: 変動費
A39: 項目 | B39: 単価 | C39: 数量 | D39: 小計 | E39: 備考
A40: 送料値引き | B40: 1000 | C40: 47 | D40: =B40*C40 -> 47000
A41: しゅわんグラス箱無し ロゴなし | B41: 460 | C41: =C15 -> 12 | D41: =B41*C41 -> 5520
A42: SHUWAN陶胎漆器 原価 | B42: 6500 | C42: =C13 -> 9 | D42: =B42*C42 -> 58500
A43: SHUWAN原価 | B43: 1260 | C43: =C20+C25+C33-C13-C15 -> 685 | D43: =B43*C43 -> 863100
A44: 桐箱&紙袋 原価 | B44: =ROUND(D44/C44,0) -> 379 | C44: =C7 -> 94 | D44: =H7 -> 35630
A45: 箱 | B45: 100 | C45: =C20+C25+C33-E45 -> 634 | D45: =B45*C45 -> 63400 | E45: 72
...

Sheet Amazon詳細
A1: 日付 | B1: トランザクションステータス | C1: トランザクションの種類 | D1: 注文番号 | E1: 商品の詳細 | F1: 商品価格合計 | G1: プロモーション割引合計 | H1: Amazon手数料 | I1: その他 | J1: 合計 (JPY) | K1: 販売数量 | L1: 桐箱1 | M1: 桐箱2
A2: 46022 | B2: 支払い実行済み | C2: 注文に対する支払い | D2: 503-6649286-7039813 | E2: SHUWAN 酒器 おちょこ ぐい呑み 日本酒グラス 270ml 磁器 日本製 ... | F2: 4527 | G2: 0 | H2: -1248 | I2: 403 | J2: 3682 | K2: 1
A3: 46022 | B3: 支払い実行済み | C3: 注文に対する支払い | D3: 503-2937518-5362243 | E3: SHUWAN 酒器 おちょこ ぐい呑み 日本酒グラス 270ml 磁器 日本製 ... | F3: 4527 | G3: 0 | H3: -1248 | I3: 403 | J3: 3682 | K3: 1
A4: 46022 | B4: 支払い実行済み | C4: 注文に対する支払い | D4: 250-6296164-1357447 | E4: SHUWAN 酒器 おちょこ ぐい呑み 日本酒グラス 270ml 磁器 日本製 ... | F4: 4527 | G4: -91 | H4: -1248 | I4: 494 | J4: 3682 | K4: 1
A5: 46022 | B5: 支払い実行済み | C5: 注文に対する支払い | D5: 503-4336827-0155041 | E5: SHUWAN 酒器 おちょこ ぐい呑み 日本酒グラス 270ml 磁器 日本製 ... | F5: 4527 | G5: -418 | H5: -1248 | I5: 821 | J5: 3682 | K5: 1
A6: 46022 | B6: 支払い実行済み | C6: 注文に対する支払い | D6: 249-4150217-0376641 | E6: SHUWAN 酒器 おちょこ ぐい呑み 日本酒グラス 270ml 磁器 日本製 ... | F6: 4527 | G6: -91 | H6: -1248 | I6: 494 | J6: 3682 | K6: 1
A7: 46021 | B7: 支払い実行済み | C7: 注文に対する支払い | D7: 249-7793879-4760669 | E7: SHUWAN 酒器 おちょこ ぐい呑み 日本酒グラス 270ml 磁器 日本製 ... | F7: 4527 | G7: 0 | H7: -1248 | I7: 403 | J7: 3682 | K7: 1
A8: 46021 | B8: 支払い実行済み | C8: 注文に対する支払い | D8: 250-0598626-1308659 | E8: SHUWAN 酒器 おちょこ ぐい呑み 日本酒グラス 270ml 磁器 日本製 ... | F8: 4527 | G8: 0 | H8: -1248 | I8: 403 | J8: 3682 | K8: 1
A9: 46021 | B9: 支払い実行済み | C9: 注文に対する支払い | D9: 250-9035096-8239861 | E9: SHUWAN 酒器 おちょこ ぐい呑み 日本酒グラス 270ml 磁器 日本製 ... | F9: 4527 | G9: 0 | H9: -1248 | I9: 403 | J9: 3682 | K9: 1
A10: 46021 | B10: 支払い実行済み | C10: 注文に対する支払い | D10: 503-5183698-0671823 | E10: SHUWAN 酒器 おちょこ ぐい呑み 日本酒グラス 270ml 磁器 日本製 ... | F10: 4527 | G10: 0 | H10: -1248 | I10: 403 | J10: 3682 | K10: 1
A11: 46021 | B11: 支払い実行済み | C11: 注文に対する支払い | D11: 249-4023392-2258251 | E11: SHUWAN 酒器 おちょこ ぐい呑み 日本酒グラス 270ml 磁器 日本製 ... | F11: 4527 | G11: 0 | H11: -1248 | I11: 403 | J11: 3682 | K11: 1
A12: 46020 | B12: 支払い実行済み | C12: 注文に対する支払い | D12: 503-2943052-3533459 | E12: SHUWAN 酒器 おちょこ ぐい呑み 日本酒グラス 270ml 磁器 日本製 ... | F12: 4527 | G12: 0 | H12: -1602 | I12: 757 | J12: 3682 | K12: 1
A13: 46020 | B13: 支払い実行済み | C13: 注文に対する支払い | D13: 503-2195641-8505421 | E13: SHUWAN 酒器 おちょこ ぐい呑み 日本酒グラス 270ml 磁器 日本製 ... | F13: 4527 | G13: 0 | H13: -1248 | I13: 403 | J13: 3682 | K13: 1
... A30: 46016 | B30: 支払い実行済み | C30: 注文に対する支払い | D30: 503-9248144-3471037 | E30: SHUWAN 酒器 おちょこ ぐい呑み 日本酒グラス 270ml 磁器 日本製 ... | F30: 4527 | G30: 0 | H30: -434 | I30: 403 | J30: 4496 | K30: 1
A31: 46015 | B31: 支払い実行済み | C31: 注文に対する支払い | D31: 503-3307929-6851023 | E31: SHUWAN 酒器 おちょこ ぐい呑み 日本酒グラス 270ml 磁器 日本製 ... | F31: 5436 | G31: 0 | H31: -455 | I31: 484 | J31: 5465 | K31: 0 | L31: 1
A32: 46015 | B32: 支払い実行済み | C32: 注文に対する支払い | D32: 250-8649563-9152657 | E32: SHUWAN 酒器 おちょこ ぐい呑み 日本酒グラス 270ml 磁器 日本製 ... | F32: 4527 | G32: 0 | H32: -434 | I32: 403 | J32: 4496 | K32: 1
A33: 46015 | B33: 支払い実行済み | C33: 注文に対する支払い | D33: 503-2889803-9219809 | E33: SHUWAN 酒器 おちょこ ぐい呑み 日本酒グラス 270ml 磁器 日本製 ... | F33: 5436 | G33: 0 | H33: -455 | I33: 484 | J33: 5465 | K33: 0 | L33: 1
A34: 46015 | B34: 支払い実行済み | C34: 注文に対する支払い | D34: 503-5256721-1386202 | E34: SHUWAN 酒器 おちょこ ぐい呑み 日本酒グラス 270ml 磁器 日本製 ... | F34: 4527 | G34: 0 | H34: -434 | I34: 403 | J34: 4496 | K34: 1
A35: 46014 | B35: 支払い実行済み | C35: 注文に対する支払い | D35: 503-4611673-3275069 | E35: SHUWAN 酒器 おちょこ ぐい呑み 日本酒グラス 270ml 磁器 日本製 ... | F35: 5436 | G35: -680 | H35: -455 | I35: 620 | J35: 4921 | K35: 0 | L35: 1
A36: 46014 | B36: 支払い実行済み | C36: 注文に対する支払い | D36: 503-0857503-1815004 | E36: SHUWAN 酒器 おちょこ ぐい呑み 日本酒グラス 270ml 磁器 日本製 ... | F36: 4527 | G36: 0 | H36: -434 | I36: 403 | J36: 4496 | K36: 1
A37: 46014 | B37: 支払い実行済み | C37: 注文に対する支払い | D37: 250-2707319-4350211 | E37: SHUWAN 酒器 おちょこ ぐい呑み 日本酒グラス 270ml 磁器 日本製 ... | F37: 5436 | G37: 0 | H37: -455 | I37: 484 | J37: 5465 | K37: 0 | L37: 1
A38: 46014 | B38: 支払い実行済み | C38: 注文に対する支払い | D38: 249-0983870-9902246 | E38: SHUWAN 酒器 おちょこ ぐい呑み 日本酒グラス 270ml 磁器 日本製 ... | F38: 4527 | G38: 0 | H38: -434 | I38: 403 | J38: 4496 | K38: 1
A39: 46014 | B39: 支払い実行済み | C39: 注文に対する支払い | D39: 503-4377943-7123015 | E39: SHUWAN 酒器 おちょこ ぐい呑み 日本酒グラス 270ml 磁器 日本製 ... | F39: 4527 | G39: 0 | H39: -434 | I39: 403 | J39: 4496 | K39: 1
A40: 46013 | B40: 支払い実行済み | C40: 注文に対する支払い | D40: 250-3699519-1138225 | E40: SHUWAN 酒器 おちょこ ぐい呑み 日本酒グラス 270ml 磁器 日本製 ... | F40: 4527 | G40: 0 | H40: -434 | I40: 403 | J40: 4496 | K40: 1
A41: 46012 | B41: 支払い実行済み | C41: 注文に対する支払い | D41: 249-1043353-5968637 | E41: SHUWAN 酒器 おちょこ ぐい呑み 日本酒グラス 270ml 磁器 日本製 ... | F41: 4527 | G41: -182 | H41: -434 | I41: 585 | J41: 4496 | K41: 1
A42: 46012 | B42: 支払い実行済み | C42: 注文に対する支払い | D42: 249-3395405-0512640 | E42: SHUWAN 酒器 おちょこ ぐい呑み 日本酒グラス 270ml 磁器 日本製 ... | F42: 4527 | G42: -455 | H42: -434 | I42: 858 | J42: 4496 | K42: 1
A43: 46012 | B43: 支払い実行済み | C43: 注文に対する支払い | D43: 503-8236909-6670250 | E43: SHUWAN 酒器 おちょこ ぐい呑み 日本酒グラス 270ml 磁器 日本製 ... | F43: 5436 | G43: 0 | H43: -455 | I43: 484 | J43: 5465 | K43: 0 | L43: 1
A44: 46012 | B44: 支払い実行済み | C44: サービス料金 | D44: --- | E44: 広告費用 | F44: 0 | G44: 0 | H44: -55001 | I44: 0 | J44: -55001 | K44: 0 | L44: 0
A45: 46012 | B45: 支払い実行済み | C45: 注文に対する支払い | D45: 503-9729954-6523011 | E45: SHUWAN 酒器 おちょこ ぐい呑み 日本酒グラス 270ml 磁器 日本製 ... | F45: 4042 | G45: 0 | H45: -434 | I45: 360 | J45: 3968 | K45: 1
A46: 46012 | B46: 支払い実行済み | C46: 注文に対する支払い | D46: 249-4898620-5908668 | E46: SHUWAN 酒器 おちょこ ぐい呑み 日本酒グラス 270ml 磁器 日本製 ... | F46: 4527 | G46: 0 | H46: -434 | I46: 403 | J46: 4496 | K46: 1
A47: 46011 | B47: 支払い実行済み | C47: 注文に対する支払い | D47: 503-7349053-0193414 | E47: SHUWAN 酒器 おちょこ ぐい呑み 日本酒グラス 270ml 磁器 日本製 ... | F47: 5436 | G47: 0 | H47: -809 | I47: 838 | J47: 5465 | K47: 0 | L47: 1
A48: 46011 | B48: 支払い実行済み | C48: 注文に対する支払い | D48: 249-8938365-4542259 | E48: SHUWAN 酒器 おちょこ ぐい呑み 日本酒グラス 270ml 磁器 日本製 ... | F48: 4527 | G48: 0 | H48: -434 | I48: 403 | J48: 4496 | K48: 1
A49: 46011 | B49: 支払い実行済み | C49: 注文に対する支払い | D49: 250-9608473-1132636 | E49: SHUWAN 酒器 おちょこ ぐい呑み 日本酒グラス 270ml 磁器 日本製 ... | F49: 4527 | G49: 0 | H49: -434 | I49: 403 | J49: 4496 | K49: 1
A50: 46010 | B50: 支払い実行済み | C50: 注文に対する支払い | D50: 250-9970434-6254266 | E50: SHUWAN 酒器 おちょこ ぐい呑み 日本酒グラス 270ml 磁器 日本製 ... | F50: 4527 | G50: 0 | H50: -434 | I50: 403 | J50: 4496 | K50: 1
A51: 46010 | B51: 支払い実行済み | C51: 注文に対する支払い | D51: 503-0674528-8679058 | E51: SHUWAN 酒器 おちょこ ぐい呑み 日本酒グラス 270ml 磁器 日本製 ... | F51: 4893 | G51: -680 | H51: -455 | I51: 626 | J51: 4384 | K51: 0 | L51: 1
A52: 46010 | B52: 支払い実行済み | C52: 注文に対する支払い | D52: 249-9667583-0266254 | E52: SHUWAN 酒器 おちょこ ぐい呑み 日本酒グラス 270ml 磁器 日本製 ... | F52: 4527 | G52: 0 | H52: -434 | I52: 403 | J52: 4496 | K52: 1
A53: 46009 | B53: 支払い実行済み | C53: 注文に対する支払い | D53: 503-8485674-7466235 | E53: SHUWAN 酒器 おちょこ ぐい呑み 日本酒グラス 270ml 磁器 日本製 ... | F53: 4527 | G53: 0 | H53: -434 | I53: 403 | J53: 4496 | K53: 1
A54: 46008 | B54: 支払い実行済み | C54: 注文に対する支払い | D54: 250-2157862-8575055 | E54: SHUWAN 酒器 おちょこ ぐい呑み 日本酒グラス 270ml 磁器 日本製 ... | F54: 4527 | G54: -140 | H54: -434 | I54: 543 | J54: 4496 | K54: 1
A55: 46008 | B55: 支払い実行済み | C55: 注文に対する支払い | D55: 249-2036494-2058221 | E55: SHUWAN 酒器 おちょこ ぐい呑み 日本酒グラス 270ml 磁器 日本製 ... | F55: 4527 | G55: 0 | H55: -434 | I55: 403 | J55: 4496 | K55: 1
A56: 46008 | B56: 支払い実行済み | C56: 注文に対する支払い | D56: 503-2685575-5218253 | E56: SHUWAN 酒器 おちょこ ぐい呑み 日本酒グラス 270ml 磁器 日本製 ... | F56: 9055 | G56: 0 | H56: -868 | I56: 805 | J56: 8992 | K56: 2
...

Sheet 留保中1月請求時確認
A1: 日付 | B1: トランザクションステータス | C1: トランザクションの種類 | D1: 注文番号 | E1: 商品の詳細 | F1: 商品価格合計 | G1: プロモーション割引合計 | H1: Amazon手数料 | I1: その他 | J1: 合計 (JPY) | K1: 番号確認
A2: 46021 | B2: 留保中 | C2: 注文に対する支払い | D2: 249-3243967-2306223 | E2: SHUWAN 酒器 おちょこ ぐい呑み 日本酒グラス 270ml 磁器 日本製 ... | F2: 9054 | G2: -1612 | H2: -2346 | I2: 1512 | J2: 6608 | K2: =VLOOKUP(D2,Amazon詳細!D:D,1,0) -> #N/A
A3: 46021 | B3: 留保中 | C3: 注文に対する支払い | D3: 250-9741592-9678248 | E3: SHUWAN 酒器 おちょこ ぐい呑み 日本酒グラス 270ml 磁器 日本製 ... | F3: 4527 | G3: 0 | H3: -1248 | I3: 403 | J3: 3682 | K3: =VLOOKUP(D3,Amazon詳細!D:D,1,0) -> #N/A
A4: 46019 | B4: 留保中 | C4: 注文に対する支払い | D4: 249-2504865-6667055 | E4: SHUWAN 酒器 おちょこ ぐい呑み 日本酒グラス 270ml 磁器 日本製 ... | F4: 4527 | G4: 0 | H4: -1248 | I4: 403 | J4: 3682 | K4: =VLOOKUP(D4,Amazon詳細!D:D,1,0) -> #N/A
A5: 46019 | B5: 留保中 | C5: 注文に対する支払い | D5: 250-3052206-1178220 | E5: SHUWAN 酒器 おちょこ ぐい呑み 日本酒グラス 270ml 磁器 日本製 ... | F5: 4527 | G5: 0 | H5: -1248 | I5: 403 | J5: 3682 | K5: =VLOOKUP(D5,Amazon詳細!D:D,1,0) -> #N/A
A6: 46019 | B6: 留保中 | C6: 注文に対する支払い | D6: 503-1737750-3501452 | E6: SHUWAN 酒器 おちょこ ぐい呑み 日本酒グラス 270ml 磁器 日本製 ... | F6: 5436 | G6: 0 | H6: -1432 | I6: 484 | J6: 4488 | K6: =VLOOKUP(D6,Amazon詳細!D:D,1,0) -> #N/A
A7: 46018 | B7: 留保中 | C7: 注文に対する支払い | D7: 249-2438002-8910245 | E7: SHUWAN 酒器 おちょこ ぐい呑み 日本酒グラス 270ml 磁器 日本製 ... | F7: 10873 | G7: 0 | H7: -2864 | I7: 967 | J7: 8976 | K7: =VLOOKUP(D7,Amazon詳細!D:D,1,0) -> #N/A
A8: 46018 | B8: 留保中 | C8: 注文に対する支払い | D8: 249-3263559-4345455 | E8: SHUWAN 酒器 おちょこ ぐい呑み 日本酒グラス 270ml 磁器 日本製 ... | F8: 18109 | G8: 0 | H8: -4992 | I8: 1611 | J8: 14728 | K8: =VLOOKUP(D8,Amazon詳細!D:D,1,0) -> #N/A
A9: 46018 | B9: 留保中 | C9: 注文に対する支払い | D9: 249-6490746-5346226 | E9: SHUWAN 酒器 おちょこ ぐい呑み 日本酒グラス 270ml 磁器 日本製 ... | F9: 4527 | G9: -418 | H9: -1248 | I9: 821 | J9: 3682 | K9: =VLOOKUP(D9,Amazon詳細!D:D,1,0) -> #N/A
A10: 46018 | B10: 留保中 | C10: 注文に対する支払い | D10: 503-3331991-7543014 | E10: SHUWAN 酒器 おちょこ ぐい呑み 日本酒グラス 270ml 磁器 日本製 ... | F10: 4527 | G10: 0 | H10: -1248 | I10: 403 | J10: 3682 | K10: =VLOOKUP(D10,Amazon詳細!D:D,1,0) -> #N/A
A11: 46018 | B11: 留保中 | C11: 注文に対する支払い | D11: 250-3143183-3017401 | E11: SHUWAN 酒器 おちょこ ぐい呑み 日本酒グラス 270ml 磁器 日本製 ... | F11: 4527 | G11: 0 | H11: -1248 | I11: 403 | J11: 3682 | K11: =VLOOKUP(D11,Amazon詳細!D:D,1,0) -> #N/A
A12: 46018 | B12: 留保中 | C12: 注文に対する支払い | D12: 503-7270054-5899043 | E12: SHUWAN 酒器 おちょこ ぐい呑み 日本酒グラス 270ml 磁器 日本製 ... | F12: 4527 | G12: 0 | H12: -1248 | I12: 403 | J12: 3682 | K12: =VLOOKUP(D12,Amazon詳細!D:D,1,0) -> #N/A
A13: 46018 | B13: 留保中 | C13: 注文に対する支払い | D13: 250-0199547-2590275 | E13: SHUWAN 酒器 おちょこ ぐい呑み 日本酒グラス 270ml 磁器 日本製 ... | F13: 4527 | G13: 0 | H13: -1248 | I13: 403 | J13: 3682 | K13: =VLOOKUP(D13,Amazon詳細!D:D,1,0) -> #N/A
... A15: 45992 | B15: 留保中 | C15: 注文に対する支払い | D15: 503-4855838-1050230 | E15: SHUWAN 酒器 おちょこ ぐい呑み 日本酒グラス 270ml 磁器 日本製 ... | F15: 4893 | G15: 0 | H15: -1334 | I15: 435 | J15: 3994 | K15: =VLOOKUP(D15,Amazon詳細!D:D,1,0) -> #N/A
K16: =VLOOKUP(D16,Amazon詳細!D:D,1,0) -> #N/A
K17: =VLOOKUP(D17,Amazon詳細!D:D,1,0) -> #N/A
K18: =VLOOKUP(D18,Amazon詳細!D:D,1,0) -> #N/A
K19: =VLOOKUP(D19,Amazon詳細!D:D,1,0) -> #N/A
K20: =VLOOKUP(D20,Amazon詳細!D:D,1,0) -> #N/A
K21: =VLOOKUP(D21,Amazon詳細!D:D,1,0) -> #N/A
K22: =VLOOKUP(D22,Amazon詳細!D:D,1,0) -> #N/A
K23: =VLOOKUP(D23,Amazon詳細!D:D,1,0) -> #N/A
K24: =VLOOKUP(D24,Amazon詳細!D:D,1,0) -> #N/A
K25: =VLOOKUP(D25,Amazon詳細!D:D,1,0) -> #N/A
K26: =VLOOKUP(D26,Amazon詳細!D:D,1,0) -> #N/A

Sheet shopify手数料試算
A1: Payout Date | B1: Status | C1: Charges | D1: Refunds | E1: Adjustments | F1: Marketplace Sales Tax | G1: Advances | H1: Reserved Funds | I1: Fees | J1: Retried Amount | K1: Total | L1: Currency | M1: 手数料率
A2: 45681 | B2: paid | C2: 55220 | D2: 0 | E2: 0 | F2: 0 | G2: 0 | H2: 0 | I2: 1993 | J2: 0 | K2: 53227 | L2: JPY | M2: =I2/K2 -> 0.037443403
A3: 45674 | B3: paid | C3: 15180 | D3: 0 | E3: 0 | F3: 0 | G3: 0 | H3: 0 | I3: 540 | J3: 0 | K3: 14640 | L3: JPY | M3: =I3/K3 -> 0.036885246
A4: 45667 | B4: paid | C4: 55220 | D4: 0 | E4: 0 | F4: 0 | G4: 0 | H4: 0 | I4: 1962 | J4: 0 | K4: 53258 | L4: JPY | M4: =I4/K4 -> 0.036839536
A5: 45663 | B5: paid | C5: 50820 | D5: 0 | E5: 0 | F5: 0 | G5: 0 | H5: 0 | I5: 1805 | J5: 0 | K5: 49015 | L5: JPY | M5: =I5/K5 -> 0.036825462
A6: 45653 | B6: paid | C6: 91300 | D6: 0 | E6: 0 | F6: 0 | G6: 0 | H6: 0 | I6: 3273 | J6: 0 | K6: 88027 | L6: JPY | M6: =I6/K6 -> 0.037181774
A7: 45646 | B7: paid | C7: 52360 | D7: 0 | E7: 0 | F7: 0 | G7: 0 | H7: 0 | I7: 1909 | J7: 0 | K7: 50451 | L7: JPY | M7: =I7/K7 -> 0.037838695
A8: 45639 | B8: paid | C8: 39380 | D8: 0 | E8: 0 | F8: 0 | G8: 0 | H8: 0 | I8: 1400 | J8: 0 | K8: 37980 | L8: JPY | M8: =I8/K8 -> 0.036861506
A9: 45632 | B9: paid | C9: 28160 | D9: 0 | E9: 0 | F9: 0 | G9: 0 | H9: 0 | I9: 1000 | J9: 0 | K9: 27160 | L9: JPY | M9: =I9/K9 -> 0.036818851
A10: 45625 | B10: paid | C10: 32120 | D10: 0 | E10: 0 | F10: 0 | G10: 0 | H10: 0 | I10: 1141 | J10: 0 | K10: 30979 | L10: JPY | M10: =I10/K10 -> 0.036831402
A11: 45618 | B11: paid | C11: 37180 | D11: 0 | E11: 0 | F11: 0 | G11: 0 | H11: 0 | I11: 1321 | J11: 0 | K11: 35859 | L11: JPY | M11: =I11/K11 -> 0.036838729
A12: 45611 | B12: paid | C12: 61380 | D12: 0 | E12: 0 | F12: 0 | G12: 0 | H12: 0 | I12: 2244 | J12: 0 | K12: 59136 | L12: JPY | M12: =I12/K12 -> 0.037946429
A13: 45604 | B13: paid | C13: 15180 | D13: 0 | E13: 0 | F13: 0 | G13: 0 | H13: 0 | I13: 540 | J13: 0 | K13: 14640 | L13: JPY | M13: =I13/K13 -> 0.036885246
... A16: 45576 | B16: paid | C16: 254320 | D16: 0 | E16: 0 | F16: 0 | G16: 0 | H16: 0 | I16: 9246 | J16: 0 | K16: 245074 | L16: JPY | M16: =I16/K16 -> 0.03772738
A17: 合計 | I17: =SUM(I2:I16) -> 35731 | K17: =SUM(K2:K16) -> 958229 | M17: =I17/K17 -> 0.037288581
